Workbook

Sheet PORTADA
C3: ANEXO D
C4: MATRIZ DE ANÁLISIS DE BRECHAS
C8: Permite identificar y evaluar las diferencias entre el estado actual de cumplimiento y el estado esperado, facilitando la priorización de acciones correctivas y oportunidades de mejora en materia de protección de datos personales.
C11: ESTUDIANTES
C12: Armijos Montoya María Milady Leiva Pazmiño Christian Andrés Valverde Vargas Pedro Eduardo
C16: Maestría en Seguridad Informática — Trabajo de Titulación

Sheet RESUMEN ANEXO
B2: ANEXO D · MATRIZ DE ANÁLISIS DE BRECHAS
B4: Objeto | C4: Identificar, priorizar y asignar responsables a las brechas de cumplimiento normativo (LOPDP/RGLOPDP), madurez institucional y gobernanza tecnológica detectadas en la autoevaluación de las cuatro instituciones educativas participantes (Institución A, B, C y D), con el fin de orientar su cierre hasta alcanzar el 100% de cumplimiento de la LOPDP.
B5: Marco de referencia | C5: Ley Orgánica de Protección de Datos Personales (LOPDP) y su Reglamento General; ISO/IEC 27001:2022 (Sistema de Gestión de Seguridad de la Información y Anexo A de controles); ISO/IEC 27701 (gestión de la privacidad); Esquema Gubernamental de Seguridad de la Información (EGSI).
B6: Fuentes de información | C6: Instrumento de Autoevaluación Institucional (Módulos 1, 2 y 3) e Informes Ejecutivos de las cuatro instituciones educativas evaluadas.
B7: Elaborado por | C7: Equipo de investigación — enfoque de seguridad de la información aplicado a la LOPDP (Ecuador).
B8: Alcance | C8: 82 criterios/dimensiones evaluados: 29 de cumplimiento normativo (Módulo 1), 25 de madurez institucional (Módulo 2) y 28 de gobernanza tecnológica (Módulo 3).
B10: METODOLOGÍA DE PRIORIZACIÓN
B11: • Cada criterio recibe un puntaje de brecha (0 a 8) que suma la situación de las 4 instituciones: No = 2 pts · Parcial = 1 pt · Sí = 0 pts (Módulos 1 y 3); Nivel de madurez 1 = 2 pts · 2 = 1.5 · 3 = 1 · 4 = 0.5 · 5 = 0 pts (Módulo 2).
B12: • Prioridad: CRÍTICA (puntaje ≥ 6) · ALTA (≥ 4) · MEDIA (≥ 2) · BAJA (< 2).
B13: • Plazo sugerido: CRÍTICA 0-3 meses · ALTA 3-6 meses · MEDIA 6-9 meses · BAJA 9-12 meses.
B14: • Cada criterio se mapea a su control correspondiente del Anexo A de ISO/IEC 27001:2022 (u otra cláusula del SGSI) y a su base legal en la LOPDP, de forma que el cierre de la brecha sea a la vez jurídicamente exigible y técnicamente auditable.
B16: CONTENIDO DEL LIBRO
B17: Matriz Consolidada | C17: Los 82 criterios con estado por institución, control ISO 27001, riesgo, acción correctiva, prioridad y plazo.
B18: Resumen Ejecutivo | C18: Tablero con brechas por módulo/institución e índice actual vs. meta de 100%.
B19: Hoja de Ruta_100pct | C19: Cronograma consolidado (0-3, 3-6, 6-9, 9-12 meses) para cerrar todas las brechas.
B20: Mapa ISO27001 | C20: Trazabilidad entre criterios LOPDP y controles del Anexo A de ISO/IEC 27001:2022.
B21: Plan_Institucion_A..D | C21: Plan de cierre de brechas específico y priorizado para cada institución.

Sheet Matriz Consolidada
B2: MATRIZ DE ANÁLISIS DE BRECHAS — DETALLE DE 82 CRITERIOS (MÓDULOS 1, 2 Y 3)
B3: Módulo | C3: ID | D3: Sección | E3: Criterio / Dimensión | F3: Base legal / Marco | G3: Control ISO/IEC 27001:2022 (Anexo A / cláusula) | H3: Estado A | I3: Estado B | J3: Estado C | K3: Estado D | L3: Pts A | M3: Pts B | N3: Pts C | O3: Pts D | P3: N° instituciones con brecha | Q3: Puntaje de brecha (0-8) | R3: Prioridad | S3: Plazo sugerido | T3: Instituciones con brecha | U3: Riesgo si no se corrige | V3: Acción correctiva recomendada | W3: Responsable sugerido | X3: Meta (100% LOPDP)
B4: M1 · Cumplimiento LOPDP/RGLOPDP | C4: A1 | D4: A. Inventario y bases de datos | E4: Identificación y registro de todas las bases de datos que contienen datos personales | F4: Art. 26, 11 y 37 LOPDP | G4: A.5.9 Inventario de información y otros activos asociados | H4: Parcial | I4: Sí | J4: Sí | K4: No | L4: =IF(ISNUMBER(H4),MAX(0,2-(H4-1)*0.5),IF(H4="No",2,IF(H4="Parcial",1,0))) -> 1 | M4: =IF(ISNUMBER(I4),MAX(0,2-(I4-1)*0.5),IF(I4="No",2,IF(I4="Parcial",1,0))) -> 0 | N4: =IF(ISNUMBER(J4),MAX(0,2-(J4-1)*0.5),IF(J4="No",2,IF(J4="Parcial",1,0))) -> 0 | O4: =IF(ISNUMBER(K4),MAX(0,2-(K4-1)*0.5),IF(K4="No",2,IF(K4="Parcial",1,0))) -> 2 | P4: =COUNTIF(L4:O4,">=1") -> 2 | Q4: =SUM(L4:O4) -> 3 | R4: =IF(Q4>=6,"CRÍTICA",IF(Q4>=4,"ALTA",IF(Q4>=2,"MEDIA","BAJA"))) -> MEDIA | S4: =IF(R4="CRÍTICA","0-3 meses",IF(R4="ALTA","3-6 meses",IF(R4="MEDIA","6-9 meses","9-12 meses"))) -> 6-9 meses | T4: A, D | U4: Sin inventario no es posible acreditar qué se trata, dónde reside ni protegerlo; imposibilita atender requerimientos de la Superintendencia y derechos ARCO+. | V4: Levantar y mantener un inventario único de bases de datos con responsable, finalidad, base de legitimación y ubicación (Registro de Actividades de Tratamiento, RAT). | W4: DPD + Secretaría/áreas dueñas de la información | X4: Sí / Cumple
B5: M1 · Cumplimiento LOPDP/RGLOPDP | C5: A2 | D5: A. Inventario y bases de datos | E5: Finalidad específica definida para cada tratamiento | F5: Art. 11 LOPDP | G5: A.5.12 Clasificación de la información | H5: Sí | I5: Sí | J5: Sí | K5: Parcial | L5: =IF(ISNUMBER(H5),MAX(0,2-(H5-1)*0.5),IF(H5="No",2,IF(H5="Parcial",1,0))) -> 0 | M5: =IF(ISNUMBER(I5),MAX(0,2-(I5-1)*0.5),IF(I5="No",2,IF(I5="Parcial",1,0))) -> 0 | N5: =IF(ISNUMBER(J5),MAX(0,2-(J5-1)*0.5),IF(J5="No",2,IF(J5="Parcial",1,0))) -> 0 | O5: =IF(ISNUMBER(K5),MAX(0,2-(K5-1)*0.5),IF(K5="No",2,IF(K5="Parcial",1,0))) -> 1 | P5: =COUNTIF(L5:O5,">=1") -> 1 | Q5: =SUM(L5:O5) -> 1 | R5: =IF(Q5>=6,"CRÍTICA",IF(Q5>=4,"ALTA",IF(Q5>=2,"MEDIA","BAJA"))) -> BAJA | S5: =IF(R5="CRÍTICA","0-3 meses",IF(R5="ALTA","3-6 meses",IF(R5="MEDIA","6-9 meses","9-12 meses"))) -> 9-12 meses | T5: D | U5: El tratamiento sin finalidad explícita habilita el uso desviado de datos (function creep) y vulnera el principio de finalidad. | V5: Documentar la finalidad de cada tratamiento en el RAT y en los avisos de privacidad correspondientes. | W5: DPD + áreas dueñas de la información | X5: Sí / Cumple
B6: M1 · Cumplimiento LOPDP/RGLOPDP | C6: A3 | D6: A. Inventario y bases de datos | E6: Documentación del período de conservación conforme a minimización y proporcionalidad | F6: Art. 10, 12 LOPDP | G6: A.5.33 Protección de los registros | H6: Sí | I6: Sí | J6: Parcial | K6: No | L6: =IF(ISNUMBER(H6),MAX(0,2-(H6-1)*0.5),IF(H6="No",2,IF(H6="Parcial",1,0))) -> 0 | M6: =IF(ISNUMBER(I6),MAX(0,2-(I6-1)*0.5),IF(I6="No",2,IF(I6="Parcial",1,0))) -> 0 | N6: =IF(ISNUMBER(J6),MAX(0,2-(J6-1)*0.5),IF(J6="No",2,IF(J6="Parcial",1,0))) -> 1 | O6: =IF(ISNUMBER(K6),MAX(0,2-(K6-1)*0.5),IF(K6="No",2,IF(K6="Parcial",1,0))) -> 2 | P6: =COUNTIF(L6:O6,">=1") -> 2 | Q6: =SUM(L6:O6) -> 3 | R6: =IF(Q6>=6,"CRÍTICA",IF(Q6>=4,"ALTA",IF(Q6>=2,"MEDIA","BAJA"))) -> MEDIA | S6: =IF(R6="CRÍTICA","0-3 meses",IF(R6="ALTA","3-6 meses",IF(R6="MEDIA","6-9 meses","9-12 meses"))) -> 6-9 meses | T6: C, D | U6: La retención indefinida de datos incrementa la superficie de exposición ante incidentes y contraviene el principio de conservación limitada. | V6: Definir y publicar una tabla de retención y eliminación de datos personales por tipo de dato y proceso. | W6: DPD + Archivo/Secretaría | X6: Sí / Cumple
B7: M1 · Cumplimiento LOPDP/RGLOPDP | C7: A4 | D7: A. Inventario y bases de datos | E7: Inventario actualizado de flujos de datos (quién recibe, quién envía, con qué propósito) | F7: Art. 26 LOPDP | G7: A.5.9 / A.8.1 Dispositivos de usuario final | H7: No | I7: No | J7: Parcial | K7: No | L7: =IF(ISNUMBER(H7),MAX(0,2-(H7-1)*0.5),IF(H7="No",2,IF(H7="Parcial",1,0))) -> 2 | M7: =IF(ISNUMBER(I7),MAX(0,2-(I7-1)*0.5),IF(I7="No",2,IF(I7="Parcial",1,0))) -> 2 | N7: =IF(ISNUMBER(J7),MAX(0,2-(J7-1)*0.5),IF(J7="No",2,IF(J7="Parcial",1,0))) -> 1 | O7: =IF(ISNUMBER(K7),MAX(0,2-(K7-1)*0.5),IF(K7="No",2,IF(K7="Parcial",1,0))) -> 2 | P7: =COUNTIF(L7:O7,">=1") -> 4 | Q7: =SUM(L7:O7) -> 7 | R7: =IF(Q7>=6,"CRÍTICA",IF(Q7>=4,"ALTA",IF(Q7>=2,"MEDIA","BAJA"))) -> CRÍTICA | S7: =IF(R7="CRÍTICA","0-3 meses",IF(R7="ALTA","3-6 meses",IF(R7="MEDIA","6-9 meses","9-12 meses"))) -> 0-3 meses | T7: A, B, C, D | U7: Sin mapa de flujos no se detectan transferencias no autorizadas a terceros o a la nube, ni se puede evaluar el riesgo de transferencias internacionales. | V7: Elaborar un diagrama de flujos de datos personales (origen, destino, medio, finalidad) y mantenerlo actualizado. | W7: DPD + TI | X7: Sí / Cumple
B8: M1 · Cumplimiento LOPDP/RGLOPDP | C8: B1 | D8: B. Consentimiento e información al titular | E8: Información al titular sobre qué datos se recopilan, cómo se usan y con quién se comparten | F8: Art. 14, 15 LOPDP | G8: A.5.34 Privacidad y protección de datos personales (PII) | H8: Sí | I8: No | J8: Parcial | K8: No | L8: =IF(ISNUMBER(H8),MAX(0,2-(H8-1)*0.5),IF(H8="No",2,IF(H8="Parcial",1,0))) -> 0 | M8: =IF(ISNUMBER(I8),MAX(0,2-(I8-1)*0.5),IF(I8="No",2,IF(I8="Parcial",1,0))) -> 2 | N8: =IF(ISNUMBER(J8),MAX(0,2-(J8-1)*0.5),IF(J8="No",2,IF(J8="Parcial",1,0))) -> 1 | O8: =IF(ISNUMBER(K8),MAX(0,2-(K8-1)*0.5),IF(K8="No",2,IF(K8="Parcial",1,0))) -> 2 | P8: =COUNTIF(L8:O8,">=1") -> 3 | Q8: =SUM(L8:O8) -> 5 | R8: =IF(Q8>=6,"CRÍTICA",IF(Q8>=4,"ALTA",IF(Q8>=2,"MEDIA","BAJA"))) -> ALTA | S8: =IF(R8="CRÍTICA","0-3 meses",IF(R8="ALTA","3-6 meses",IF(R8="MEDIA","6-9 meses","9-12 meses"))) -> 3-6 meses | T8: B, C, D | U8: La falta de información transparente impide el consentimiento válido e informado y expone a sanciones por falta de transparencia. | V8: Publicar avisos de privacidad claros y accesibles (portal web, matrícula, carteleras) para cada finalidad de tratamiento. | W8: DPD + Comunicación/Secretaría | X8: Sí / Cumple
B9: M1 · Cumplimiento LOPDP/RGLOPDP | C9: B2 | D9: B. Consentimiento e información al titular | E9: Obtención de consentimiento explícito antes de recopilar o procesar datos personales | F9: Art. 9 LOPDP | G9: A.5.34 Privacidad y protección de datos personales (PII) | H9: Sí | I9: No | J9: Parcial | K9: No | L9: =IF(ISNUMBER(H9),MAX(0,2-(H9-1)*0.5),IF(H9="No",2,IF(H9="Parcial",1,0))) -> 0 | M9: =IF(ISNUMBER(I9),MAX(0,2-(I9-1)*0.5),IF(I9="No",2,IF(I9="Parcial",1,0))) -> 2 | N9: =IF(ISNUMBER(J9),MAX(0,2-(J9-1)*0.5),IF(J9="No",2,IF(J9="Parcial",1,0))) -> 1 | O9: =IF(ISNUMBER(K9),MAX(0,2-(K9-1)*0.5),IF(K9="No",2,IF(K9="Parcial",1,0))) -> 2 | P9: =COUNTIF(L9:O9,">=1") -> 3 | Q9: =SUM(L9:O9) -> 5 | R9: =IF(Q9>=6,"CRÍTICA",IF(Q9>=4,"ALTA",IF(Q9>=2,"MEDIA","BAJA"))) -> ALTA | S9: =IF(R9="CRÍTICA","0-3 meses",IF(R9="ALTA","3-6 meses",IF(R9="MEDIA","6-9 meses","9-12 meses"))) -> 3-6 meses | T9: B, C, D | U9: El tratamiento sin consentimiento válido (o sin otra base de legitimación) constituye una infracción directa y es la causal más común de sanción. | V9: Implementar un formato de consentimiento informado (físico o digital) con registro de evidencia, diferenciado por finalidad. | W9: DPD + Secretaría | X9: Sí / Cumple
B10: M1 · Cumplimiento LOPDP/RGLOPDP | C10: B3 | D10: B. Consentimiento e información al titular | E10: Política de privacidad clara, accesible y revisada periódicamente | F10: Art. 14 LOPDP | G10: A.5.1 Políticas de seguridad de la información | H10: Parcial | I10: Sí | J10: No | K10: Parcial | L10: =IF(ISNUMBER(H10),MAX(0,2-(H10-1)*0.5),IF(H10="No",2,IF(H10="Parcial",1,0))) -> 1 | M10: =IF(ISNUMBER(I10),MAX(0,2-(I10-1)*0.5),IF(I10="No",2,IF(I10="Parcial",1,0))) -> 0 | N10: =IF(ISNUMBER(J10),MAX(0,2-(J10-1)*0.5),IF(J10="No",2,IF(J10="Parcial",1,0))) -> 2 | O10: =IF(ISNUMBER(K10),MAX(0,2-(K10-1)*0.5),IF(K10="No",2,IF(K10="Parcial",1,0))) -> 1 | P10: =COUNTIF(L10:O10,">=1") -> 3 | Q10: =SUM(L10:O10) -> 4 | R10: =IF(Q10>=6,"CRÍTICA",IF(Q10>=4,"ALTA",IF(Q10>=2,"MEDIA","BAJA"))) -> ALTA | S10: =IF(R10="CRÍTICA","0-3 meses",IF(R10="ALTA","3-6 meses",IF(R10="MEDIA","6-9 meses","9-12 meses"))) -> 3-6 meses | T10: A, C, D | U10: Una política ausente o desactualizada deja sin marco de referencia a la comunidad educativa y al personal encargado del tratamiento. | V10: Redactar, aprobar y publicar la política institucional de protección de datos personales; revisarla al menos una vez al año. | W10: Dirección + DPD | X10: Sí / Cumple
B11: M1 · Cumplimiento LOPDP/RGLOPDP | C11: B4 | D11: B. Consentimiento e información al titular | E11: Información a los titulares sobre cómo ejercer sus derechos ARCO+ | F11: Art. 19-25 LOPDP | G11: A.5.34 Privacidad y protección de datos personales (PII) | H11: No | I11: Sí | J11: No | K11: Parcial | L11: =IF(ISNUMBER(H11),MAX(0,2-(H11-1)*0.5),IF(H11="No",2,IF(H11="Parcial",1,0))) -> 2 | M11: =IF(ISNUMBER(I11),MAX(0,2-(I11-1)*0.5),IF(I11="No",2,IF(I11="Parcial",1,0))) -> 0 | N11: =IF(ISNUMBER(J11),MAX(0,2-(J11-1)*0.5),IF(J11="No",2,IF(J11="Parcial",1,0))) -> 2 | O11: =IF(ISNUMBER(K11),MAX(0,2-(K11-1)*0.5),IF(K11="No",2,IF(K11="Parcial",1,0))) -> 1 | P11: =COUNTIF(L11:O11,">=1") -> 3 | Q11: =SUM(L11:O11) -> 5 | R11: =IF(Q11>=6,"CRÍTICA",IF(Q11>=4,"ALTA",IF(Q11>=2,"MEDIA","BAJA"))) -> ALTA | S11: =IF(R11="CRÍTICA","0-3 meses",IF(R11="ALTA","3-6 meses",IF(R11="MEDIA","6-9 meses","9-12 meses"))) -> 3-6 meses | T11: A, C, D | U11: Los titulares no pueden ejercer derechos que desconocen, lo que perpetúa el uso de datos sin control del titular. | V11: Incluir en avisos de privacidad y canales institucionales el procedimiento y medios para ejercer derechos ARCO+. | W11: DPD + Comunicación | X11: Sí / Cumple
B12: M1 · Cumplimiento LOPDP/RGLOPDP | C12: B5 | D12: B. Consentimiento e información al titular | E12: Política de uso de cookies con consentimiento informado | F12: Art. 8, 9 y 14 LOPDP | G12: A.5.34 Privacidad y protección de datos personales (PII) | H12: No | I12: No | J12: No | K12: No | L12: =IF(ISNUMBER(H12),MAX(0,2-(H12-1)*0.5),IF(H12="No",2,IF(H12="Parcial",1,0))) -> 2 | M12: =IF(ISNUMBER(I12),MAX(0,2-(I12-1)*0.5),IF(I12="No",2,IF(I12="Parcial",1,0))) -> 2 | N12: =IF(ISNUMBER(J12),MAX(0,2-(J12-1)*0.5),IF(J12="No",2,IF(J12="Parcial",1,0))) -> 2 | O12: =IF(ISNUMBER(K12),MAX(0,2-(K12-1)*0.5),IF(K12="No",2,IF(K12="Parcial",1,0))) -> 2 | P12: =COUNTIF(L12:O12,">=1") -> 4 | Q12: =SUM(L12:O12) -> 8 | R12: =IF(Q12>=6,"CRÍTICA",IF(Q12>=4,"ALTA",IF(Q12>=2,"MEDIA","BAJA"))) -> CRÍTICA | S12: =IF(R12="CRÍTICA","0-3 meses",IF(R12="ALTA","3-6 meses",IF(R12="MEDIA","6-9 meses","9-12 meses"))) -> 0-3 meses | T12: A, B, C, D | U12: El uso de cookies o rastreo sin consentimiento en plataformas institucionales expone a tratamiento no autorizado de datos de navegación. | V12: Implementar aviso/banner de cookies con opciones de aceptación granular en los sitios y plataformas institucionales. | W12: TI + DPD | X12: Sí / Cumple
B13: M1 · Cumplimiento LOPDP/RGLOPDP | C13: C1 | D13: C. Derechos de los titulares (ARCO+) | E13: Mecanismo formal para atender solicitudes de Acceso a datos personales | F13: Art. 19 LOPDP | G13: A.5.34 Privacidad y protección de datos personales (PII) | H13: Parcial | I13: Sí | J13: Parcial | K13: No | L13: =IF(ISNUMBER(H13),MAX(0,2-(H13-1)*0.5),IF(H13="No",2,IF(H13="Parcial",1,0))) -> 1 | M13: =IF(ISNUMBER(I13),MAX(0,2-(I13-1)*0.5),IF(I13="No",2,IF(I13="Parcial",1,0))) -> 0 | N13: =IF(ISNUMBER(J13),MAX(0,2-(J13-1)*0.5),IF(J13="No",2,IF(J13="Parcial",1,0))) -> 1 | O13: =IF(ISNUMBER(K13),MAX(0,2-(K13-1)*0.5),IF(K13="No",2,IF(K13="Parcial",1,0))) -> 2 | P13: =COUNTIF(L13:O13,">=1") -> 3 | Q13: =SUM(L13:O13) -> 4 | R13: =IF(Q13>=6,"CRÍTICA",IF(Q13>=4,"ALTA",IF(Q13>=2,"MEDIA","BAJA"))) -> ALTA | S13: =IF(R13="CRÍTICA","0-3 meses",IF(R13="ALTA","3-6 meses",IF(R13="MEDIA","6-9 meses","9-12 meses"))) -> 3-6 meses | T13: A, C, D | U13: La ausencia de canal formal deriva en respuestas informales, fuera de plazo o inexistentes, con riesgo de sanción y pérdida de confianza. | V13: Crear un procedimiento documentado (formulario, canal y plazos) para solicitudes de acceso. | W13: DPD + Secretaría | X13: Sí / Cumple
B14: M1 · Cumplimiento LOPDP/RGLOPDP | C14: C2 | D14: C. Derechos de los titulares (ARCO+) | E14: Mecanismo formal para solicitudes de Rectificación de datos | F14: Art. 20 LOPDP | G14: A.5.34 Privacidad y protección de datos personales (PII) | H14: Parcial | I14: Sí | J14: Parcial | K14: No | L14: =IF(ISNUMBER(H14),MAX(0,2-(H14-1)*0.5),IF(H14="No",2,IF(H14="Parcial",1,0))) -> 1 | M14: =IF(ISNUMBER(I14),MAX(0,2-(I14-1)*0.5),IF(I14="No",2,IF(I14="Parcial",1,0))) -> 0 | N14: =IF(ISNUMBER(J14),MAX(0,2-(J14-1)*0.5),IF(J14="No",2,IF(J14="Parcial",1,0))) -> 1 | O14: =IF(ISNUMBER(K14),MAX(0,2-(K14-1)*0.5),IF(K14="No",2,IF(K14="Parcial",1,0))) -> 2 | P14: =COUNTIF(L14:O14,">=1") -> 3 | Q14: =SUM(L14:O14) -> 4 | R14: =IF(Q14>=6,"CRÍTICA",IF(Q14>=4,"ALTA",IF(Q14>=2,"MEDIA","BAJA"))) -> ALTA | S14: =IF(R14="CRÍTICA","0-3 meses",IF(R14="ALTA","3-6 meses",IF(R14="MEDIA","6-9 meses","9-12 meses"))) -> 3-6 meses | T14: A, C, D | U14: Datos inexactos no corregidos afectan decisiones académicas/administrativas y vulneran el derecho de rectificación. | V14: Extender el procedimiento de derechos ARCO+ para incluir rectificación con verificación de identidad y trazabilidad del cambio. | W14: DPD + Secretaría | X14: Sí / Cumple
B15: M1 · Cumplimiento LOPDP/RGLOPDP | C15: C3 | D15: C. Derechos de los titulares (ARCO+) | E15: Mecanismo formal para solicitudes de Cancelación / Supresión de datos | F15: Art. 21 LOPDP | G15: A.5.34 Privacidad y protección de datos personales (PII) | H15: No | I15: No | J15: Parcial | K15: No | L15: =IF(ISNUMBER(H15),MAX(0,2-(H15-1)*0.5),IF(H15="No",2,IF(H15="Parcial",1,0))) -> 2 | M15: =IF(ISNUMBER(I15),MAX(0,2-(I15-1)*0.5),IF(I15="No",2,IF(I15="Parcial",1,0))) -> 2 | N15: =IF(ISNUMBER(J15),MAX(0,2-(J15-1)*0.5),IF(J15="No",2,IF(J15="Parcial",1,0))) -> 1 | O15: =IF(ISNUMBER(K15),MAX(0,2-(K15-1)*0.5),IF(K15="No",2,IF(K15="Parcial",1,0))) -> 2 | P15: =COUNTIF(L15:O15,">=1") -> 4 | Q15: =SUM(L15:O15) -> 7 | R15: =IF(Q15>=6,"CRÍTICA",IF(Q15>=4,"ALTA",IF(Q15>=2,"MEDIA","BAJA"))) -> CRÍTICA | S15: =IF(R15="CRÍTICA","0-3 meses",IF(R15="ALTA","3-6 meses",IF(R15="MEDIA","6-9 meses","9-12 meses"))) -> 0-3 meses | T15: A, B, C, D | U15: Sin procedimiento de supresión, los datos se conservan más allá de lo necesario incluso cuando el titular lo solicita. | V15: Definir el procedimiento y las excepciones legales de conservación aplicables a la supresión de datos. | W15: DPD + Secretaría/Archivo | X15: Sí / Cumple
... B32: M1 · Cumplimiento LOPDP/RGLOPDP | C32: F4 | D32: F. Auditoría, capacitación y mejora continua | E32: Pruebas de penetración o análisis de seguridad informática | F32: Art. 37 y 40 LOPDP | G32: A.8.29 Pruebas de seguridad en el desarrollo y aceptación / A.5.36 Cumplimiento de políticas | H32: Sí | I32: Parcial | J32: No | K32: No | L32: =IF(ISNUMBER(H32),MAX(0,2-(H32-1)*0.5),IF(H32="No",2,IF(H32="Parcial",1,0))) -> 0 | M32: =IF(ISNUMBER(I32),MAX(0,2-(I32-1)*0.5),IF(I32="No",2,IF(I32="Parcial",1,0))) -> 1 | N32: =IF(ISNUMBER(J32),MAX(0,2-(J32-1)*0.5),IF(J32="No",2,IF(J32="Parcial",1,0))) -> 2 | O32: =IF(ISNUMBER(K32),MAX(0,2-(K32-1)*0.5),IF(K32="No",2,IF(K32="Parcial",1,0))) -> 2 | P32: =COUNTIF(L32:O32,">=1") -> 3 | Q32: =SUM(L32:O32) -> 5 | R32: =IF(Q32>=6,"CRÍTICA",IF(Q32>=4,"ALTA",IF(Q32>=2,"MEDIA","BAJA"))) -> ALTA | S32: =IF(R32="CRÍTICA","0-3 meses",IF(R32="ALTA","3-6 meses",IF(R32="MEDIA","6-9 meses","9-12 meses"))) -> 3-6 meses | T32: B, C, D | U32: Sin pruebas de seguridad periódicas, las vulnerabilidades explotables permanecen sin detectar hasta que ocurre un incidente real. | V32: Contratar o ejecutar pruebas de seguridad (pentesting/vulnerability assessment) al menos una vez al año sobre sistemas críticos. | W32: TI | X32: Sí / Cumple
B33: M2 · Madurez Institucional | C33: G1 | D33: I. Gobernanza y liderazgo en datos | E33: Estructura de gobierno de datos con roles y responsabilidades definidos (Responsable, DPD, Encargados) | F33: Art. 47-50 LOPDP | G33: A.5.2 Roles y responsabilidades de seguridad de la información | H33: 1 | I33: 1 | J33: 1 | K33: 1 | L33: =IF(ISNUMBER(H33),MAX(0,2-(H33-1)*0.5),IF(H33="No",2,IF(H33="Parcial",1,0))) -> 2 | M33: =IF(ISNUMBER(I33),MAX(0,2-(I33-1)*0.5),IF(I33="No",2,IF(I33="Parcial",1,0))) -> 2 | N33: =IF(ISNUMBER(J33),MAX(0,2-(J33-1)*0.5),IF(J33="No",2,IF(J33="Parcial",1,0))) -> 2 | O33: =IF(ISNUMBER(K33),MAX(0,2-(K33-1)*0.5),IF(K33="No",2,IF(K33="Parcial",1,0))) -> 2 | P33: =COUNTIF(L33:O33,">=1") -> 4 | Q33: =SUM(L33:O33) -> 8 | R33: =IF(Q33>=6,"CRÍTICA",IF(Q33>=4,"ALTA",IF(Q33>=2,"MEDIA","BAJA"))) -> CRÍTICA | S33: =IF(R33="CRÍTICA","0-3 meses",IF(R33="ALTA","3-6 meses",IF(R33="MEDIA","6-9 meses","9-12 meses"))) -> 0-3 meses | T33: A, B, C, D | U33: Sin estructura de gobierno, nadie es responsable formal de decisiones sobre datos personales, dificultando la rendición de cuentas. | V33: Definir y aprobar formalmente el organigrama de gobierno de datos (RACI) con Responsable, DPD y Encargados. | W33: Dirección | X33: Nivel 5 / Optimizado
B34: M2 · Madurez Institucional | C34: G2 | D34: I. Gobernanza y liderazgo en datos | E34: Liderazgo y compromiso de la alta dirección con el cumplimiento normativo | F34: Art. 47-50 LOPDP | G34: Cláusula 5.1 Liderazgo y compromiso | H34: 3 | I34: 1 | J34: 2 | K34: 2 | L34: =IF(ISNUMBER(H34),MAX(0,2-(H34-1)*0.5),IF(H34="No",2,IF(H34="Parcial",1,0))) -> 1 | M34: =IF(ISNUMBER(I34),MAX(0,2-(I34-1)*0.5),IF(I34="No",2,IF(I34="Parcial",1,0))) -> 2 | N34: =IF(ISNUMBER(J34),MAX(0,2-(J34-1)*0.5),IF(J34="No",2,IF(J34="Parcial",1,0))) -> 1.5 | O34: =IF(ISNUMBER(K34),MAX(0,2-(K34-1)*0.5),IF(K34="No",2,IF(K34="Parcial",1,0))) -> 1.5 | P34: =COUNTIF(L34:O34,">=1") -> 4 | Q34: =SUM(L34:O34) -> 6 | R34: =IF(Q34>=6,"CRÍTICA",IF(Q34>=4,"ALTA",IF(Q34>=2,"MEDIA","BAJA"))) -> CRÍTICA | S34: =IF(R34="CRÍTICA","0-3 meses",IF(R34="ALTA","3-6 meses",IF(R34="MEDIA","6-9 meses","9-12 meses"))) -> 0-3 meses | T34: A, B, C, D | U34: Sin patrocinio directivo, las iniciativas de cumplimiento carecen de recursos y prioridad institucional. | V34: Incluir la protección de datos como punto permanente en la planificación estratégica y en los comités de dirección. | W34: Rectorado/Dirección | X34: Nivel 5 / Optimizado
B35: M2 · Madurez Institucional | C35: G3 | D35: I. Gobernanza y liderazgo en datos | E35: Políticas institucionales formalizadas sobre privacidad y protección de datos personales | F35: Art. 14 LOPDP | G35: A.5.1 Políticas de seguridad de la información | H35: 1 | I35: 3 | J35: 2 | K35: 1 | L35: =IF(ISNUMBER(H35),MAX(0,2-(H35-1)*0.5),IF(H35="No",2,IF(H35="Parcial",1,0))) -> 2 | M35: =IF(ISNUMBER(I35),MAX(0,2-(I35-1)*0.5),IF(I35="No",2,IF(I35="Parcial",1,0))) -> 1 | N35: =IF(ISNUMBER(J35),MAX(0,2-(J35-1)*0.5),IF(J35="No",2,IF(J35="Parcial",1,0))) -> 1.5 | O35: =IF(ISNUMBER(K35),MAX(0,2-(K35-1)*0.5),IF(K35="No",2,IF(K35="Parcial",1,0))) -> 2 | P35: =COUNTIF(L35:O35,">=1") -> 4 | Q35: =SUM(L35:O35) -> 6.5 | R35: =IF(Q35>=6,"CRÍTICA",IF(Q35>=4,"ALTA",IF(Q35>=2,"MEDIA","BAJA"))) -> CRÍTICA | S35: =IF(R35="CRÍTICA","0-3 meses",IF(R35="ALTA","3-6 meses",IF(R35="MEDIA","6-9 meses","9-12 meses"))) -> 0-3 meses | T35: A, B, C, D | U35: La falta de política formal deja los criterios de protección de datos a decisiones ad hoc, inconsistentes entre áreas. | V35: Aprobar y difundir la política institucional de protección de datos personales. | W35: Dirección + DPD | X35: Nivel 5 / Optimizado
B36: M2 · Madurez Institucional | C36: G4 | D36: I. Gobernanza y liderazgo en datos | E36: Presupuesto asignado para actividades de cumplimiento y protección de datos | F36: Art. 47-50 LOPDP | G36: Cláusula 7.1 Recursos | H36: 5 | I36: 2 | J36: 1 | K36: 1 | L36: =IF(ISNUMBER(H36),MAX(0,2-(H36-1)*0.5),IF(H36="No",2,IF(H36="Parcial",1,0))) -> 0 | M36: =IF(ISNUMBER(I36),MAX(0,2-(I36-1)*0.5),IF(I36="No",2,IF(I36="Parcial",1,0))) -> 1.5 | N36: =IF(ISNUMBER(J36),MAX(0,2-(J36-1)*0.5),IF(J36="No",2,IF(J36="Parcial",1,0))) -> 2 | O36: =IF(ISNUMBER(K36),MAX(0,2-(K36-1)*0.5),IF(K36="No",2,IF(K36="Parcial",1,0))) -> 2 | P36: =COUNTIF(L36:O36,">=1") -> 3 | Q36: =SUM(L36:O36) -> 5.5 | R36: =IF(Q36>=6,"CRÍTICA",IF(Q36>=4,"ALTA",IF(Q36>=2,"MEDIA","BAJA"))) -> ALTA | S36: =IF(R36="CRÍTICA","0-3 meses",IF(R36="ALTA","3-6 meses",IF(R36="MEDIA","6-9 meses","9-12 meses"))) -> 3-6 meses | T36: B, C, D | U36: Sin presupuesto, ninguna de las acciones correctivas de este plan es sostenible en el tiempo. | V36: Asignar una partida presupuestaria anual específica para protección de datos y seguridad de la información. | W36: Dirección/Financiero | X36: Nivel 5 / Optimizado
B37: M2 · Madurez Institucional | C37: P1 | D37: II. Gestión de procesos y procedimientos | E37: Procesos de tratamiento de datos documentados, aprobados y comunicados al personal | F37: Art. 37 LOPDP | G37: A.5.37 Procedimientos operativos documentados | H37: 1 | I37: 2 | J37: 2 | K37: 1 | L37: =IF(ISNUMBER(H37),MAX(0,2-(H37-1)*0.5),IF(H37="No",2,IF(H37="Parcial",1,0))) -> 2 | M37: =IF(ISNUMBER(I37),MAX(0,2-(I37-1)*0.5),IF(I37="No",2,IF(I37="Parcial",1,0))) -> 1.5 | N37: =IF(ISNUMBER(J37),MAX(0,2-(J37-1)*0.5),IF(J37="No",2,IF(J37="Parcial",1,0))) -> 1.5 | O37: =IF(ISNUMBER(K37),MAX(0,2-(K37-1)*0.5),IF(K37="No",2,IF(K37="Parcial",1,0))) -> 2 | P37: =COUNTIF(L37:O37,">=1") -> 4 | Q37: =SUM(L37:O37) -> 7 | R37: =IF(Q37>=6,"CRÍTICA",IF(Q37>=4,"ALTA",IF(Q37>=2,"MEDIA","BAJA"))) -> CRÍTICA | S37: =IF(R37="CRÍTICA","0-3 meses",IF(R37="ALTA","3-6 meses",IF(R37="MEDIA","6-9 meses","9-12 meses"))) -> 0-3 meses | T37: A, B, C, D | U37: Procesos no documentados dependen de la memoria de personas concretas, generando inconsistencia y pérdida de conocimiento ante rotación de personal. | V37: Documentar y aprobar los procedimientos clave de tratamiento de datos y capacitar al personal en su aplicación. | W37: DPD + dueños de proceso | X37: Nivel 5 / Optimizado
B38: M2 · Madurez Institucional | C38: P2 | D38: II. Gestión de procesos y procedimientos | E38: Registro de Actividades de Tratamiento (RAT) actualizado | F38: Art. 26 LOPDP | G38: A.5.9 Inventario de información y otros activos asociados | H38: 1 | I38: 1 | J38: 1 | K38: 1 | L38: =IF(ISNUMBER(H38),MAX(0,2-(H38-1)*0.5),IF(H38="No",2,IF(H38="Parcial",1,0))) -> 2 | M38: =IF(ISNUMBER(I38),MAX(0,2-(I38-1)*0.5),IF(I38="No",2,IF(I38="Parcial",1,0))) -> 2 | N38: =IF(ISNUMBER(J38),MAX(0,2-(J38-1)*0.5),IF(J38="No",2,IF(J38="Parcial",1,0))) -> 2 | O38: =IF(ISNUMBER(K38),MAX(0,2-(K38-1)*0.5),IF(K38="No",2,IF(K38="Parcial",1,0))) -> 2 | P38: =COUNTIF(L38:O38,">=1") -> 4 | Q38: =SUM(L38:O38) -> 8 | R38: =IF(Q38>=6,"CRÍTICA",IF(Q38>=4,"ALTA",IF(Q38>=2,"MEDIA","BAJA"))) -> CRÍTICA | S38: =IF(R38="CRÍTICA","0-3 meses",IF(R38="ALTA","3-6 meses",IF(R38="MEDIA","6-9 meses","9-12 meses"))) -> 0-3 meses | T38: A, B, C, D | U38: Un RAT desactualizado o inexistente impide demostrar cumplimiento ante la autoridad de control. | V38: Levantar el RAT y establecer una revisión periódica (al menos semestral) para mantenerlo vigente. | W38: DPD | X38: Nivel 5 / Optimizado
B39: M2 · Madurez Institucional | C39: P3 | D39: II. Gestión de procesos y procedimientos | E39: Procedimientos formales para responder derechos ARCO+ de los titulares | F39: Art. 19-25 LOPDP | G39: A.5.34 Privacidad y protección de datos personales (PII) | H39: 1 | I39: 1 | J39: 1 | K39: 1 | L39: =IF(ISNUMBER(H39),MAX(0,2-(H39-1)*0.5),IF(H39="No",2,IF(H39="Parcial",1,0))) -> 2 | M39: =IF(ISNUMBER(I39),MAX(0,2-(I39-1)*0.5),IF(I39="No",2,IF(I39="Parcial",1,0))) -> 2 | N39: =IF(ISNUMBER(J39),MAX(0,2-(J39-1)*0.5),IF(J39="No",2,IF(J39="Parcial",1,0))) -> 2 | O39: =IF(ISNUMBER(K39),MAX(0,2-(K39-1)*0.5),IF(K39="No",2,IF(K39="Parcial",1,0))) -> 2 | P39: =COUNTIF(L39:O39,">=1") -> 4 | Q39: =SUM(L39:O39) -> 8 | R39: =IF(Q39>=6,"CRÍTICA",IF(Q39>=4,"ALTA",IF(Q39>=2,"MEDIA","BAJA"))) -> CRÍTICA | S39: =IF(R39="CRÍTICA","0-3 meses",IF(R39="ALTA","3-6 meses",IF(R39="MEDIA","6-9 meses","9-12 meses"))) -> 0-3 meses | T39: A, B, C, D | U39: La ausencia de procedimiento formal deriva en respuestas inconsistentes o fuera de plazo a los titulares. | V39: Formalizar el procedimiento único de atención de derechos ARCO+ (ver Módulo 1, sección C). | W39: DPD | X39: Nivel 5 / Optimizado
B40: M2 · Madurez Institucional | C40: P4 | D40: II. Gestión de procesos y procedimientos | E40: Procedimientos para gestión de incidentes y brechas de datos | F40: Art. 42 y 44 LOPDP | G40: A.5.24 Planificación y preparación de la gestión de incidentes | H40: 3 | I40: 1 | J40: 1 | K40: 1 | L40: =IF(ISNUMBER(H40),MAX(0,2-(H40-1)*0.5),IF(H40="No",2,IF(H40="Parcial",1,0))) -> 1 | M40: =IF(ISNUMBER(I40),MAX(0,2-(I40-1)*0.5),IF(I40="No",2,IF(I40="Parcial",1,0))) -> 2 | N40: =IF(ISNUMBER(J40),MAX(0,2-(J40-1)*0.5),IF(J40="No",2,IF(J40="Parcial",1,0))) -> 2 | O40: =IF(ISNUMBER(K40),MAX(0,2-(K40-1)*0.5),IF(K40="No",2,IF(K40="Parcial",1,0))) -> 2 | P40: =COUNTIF(L40:O40,">=1") -> 4 | Q40: =SUM(L40:O40) -> 7 | R40: =IF(Q40>=6,"CRÍTICA",IF(Q40>=4,"ALTA",IF(Q40>=2,"MEDIA","BAJA"))) -> CRÍTICA | S40: =IF(R40="CRÍTICA","0-3 meses",IF(R40="ALTA","3-6 meses",IF(R40="MEDIA","6-9 meses","9-12 meses"))) -> 0-3 meses | T40: A, B, C, D | U40: Sin procedimiento, la respuesta ante una brecha real será improvisada, tardía y con mayor impacto legal y reputacional. | V40: Aprobar el procedimiento de gestión de incidentes de seguridad de la información con roles y tiempos de respuesta. | W40: TI + DPD | X40: Nivel 5 / Optimizado
B41: M2 · Madurez Institucional | C41: P5 | D41: II. Gestión de procesos y procedimientos | E41: Proceso de revisión y mejora continua de los procedimientos de protección de datos | F41: Art. 47 LOPDP | G41: Cláusula 10.1 Mejora continua | H41: 1 | I41: 1 | J41: 1 | K41: 1 | L41: =IF(ISNUMBER(H41),MAX(0,2-(H41-1)*0.5),IF(H41="No",2,IF(H41="Parcial",1,0))) -> 2 | M41: =IF(ISNUMBER(I41),MAX(0,2-(I41-1)*0.5),IF(I41="No",2,IF(I41="Parcial",1,0))) -> 2 | N41: =IF(ISNUMBER(J41),MAX(0,2-(J41-1)*0.5),IF(J41="No",2,IF(J41="Parcial",1,0))) -> 2 | O41: =IF(ISNUMBER(K41),MAX(0,2-(K41-1)*0.5),IF(K41="No",2,IF(K41="Parcial",1,0))) -> 2 | P41: =COUNTIF(L41:O41,">=1") -> 4 | Q41: =SUM(L41:O41) -> 8 | R41: =IF(Q41>=6,"CRÍTICA",IF(Q41>=4,"ALTA",IF(Q41>=2,"MEDIA","BAJA"))) -> CRÍTICA | S41: =IF(R41="CRÍTICA","0-3 meses",IF(R41="ALTA","3-6 meses",IF(R41="MEDIA","6-9 meses","9-12 meses"))) -> 0-3 meses | T41: A, B, C, D | U41: Procedimientos que no se revisan quedan obsoletos frente a cambios normativos, tecnológicos u organizacionales. | V41: Establecer un ciclo anual de revisión de procedimientos de protección de datos, con responsable y fecha de revisión. | W41: DPD | X41: Nivel 5 / Optimizado
B42: M2 · Madurez Institucional | C42: CC1 | D42: III. Cultura y capacitación organizacional | E42: Conocimiento básico del personal sobre la LOPDP y sus obligaciones | F42: Art. 37 LOPDP | G42: A.6.3 Concienciación, educación y formación en seguridad de la información | H42: 3 | I42: 2 | J42: 2 | K42: 1 | L42: =IF(ISNUMBER(H42),MAX(0,2-(H42-1)*0.5),IF(H42="No",2,IF(H42="Parcial",1,0))) -> 1 | M42: =IF(ISNUMBER(I42),MAX(0,2-(I42-1)*0.5),IF(I42="No",2,IF(I42="Parcial",1,0))) -> 1.5 | N42: =IF(ISNUMBER(J42),MAX(0,2-(J42-1)*0.5),IF(J42="No",2,IF(J42="Parcial",1,0))) -> 1.5 | O42: =IF(ISNUMBER(K42),MAX(0,2-(K42-1)*0.5),IF(K42="No",2,IF(K42="Parcial",1,0))) -> 2 | P42: =COUNTIF(L42:O42,">=1") -> 4 | Q42: =SUM(L42:O42) -> 6 | R42: =IF(Q42>=6,"CRÍTICA",IF(Q42>=4,"ALTA",IF(Q42>=2,"MEDIA","BAJA"))) -> CRÍTICA | S42: =IF(R42="CRÍTICA","0-3 meses",IF(R42="ALTA","3-6 meses",IF(R42="MEDIA","6-9 meses","9-12 meses"))) -> 0-3 meses | T42: A, B, C, D | U42: Personal sin conocimiento básico de la ley no puede identificar ni prevenir incumplimientos en su labor diaria. | V42: Difundir una guía básica de LOPDP a todo el personal como parte de la inducción institucional. | W42: Talento Humano | X42: Nivel 5 / Optimizado
B43: M2 · Madurez Institucional | C43: CC2 | D43: III. Cultura y capacitación organizacional | E43: Capacitaciones formales y periódicas sobre protección de datos a todos los niveles | F43: Art. 37 LOPDP | G43: A.6.3 Concienciación, educación y formación en seguridad de la información | H43: 1 | I43: 1 | J43: 2 | K43: 1 | L43: =IF(ISNUMBER(H43),MAX(0,2-(H43-1)*0.5),IF(H43="No",2,IF(H43="Parcial",1,0))) -> 2 | M43: =IF(ISNUMBER(I43),MAX(0,2-(I43-1)*0.5),IF(I43="No",2,IF(I43="Parcial",1,0))) -> 2 | N43: =IF(ISNUMBER(J43),MAX(0,2-(J43-1)*0.5),IF(J43="No",2,IF(J43="Parcial",1,0))) -> 1.5 | O43: =IF(ISNUMBER(K43),MAX(0,2-(K43-1)*0.5),IF(K43="No",2,IF(K43="Parcial",1,0))) -> 2 | P43: =COUNTIF(L43:O43,">=1") -> 4 | Q43: =SUM(L43:O43) -> 7.5 | R43: =IF(Q43>=6,"CRÍTICA",IF(Q43>=4,"ALTA",IF(Q43>=2,"MEDIA","BAJA"))) -> CRÍTICA | S43: =IF(R43="CRÍTICA","0-3 meses",IF(R43="ALTA","3-6 meses",IF(R43="MEDIA","6-9 meses","9-12 meses"))) -> 0-3 meses | T43: A, B, C, D | U43: La capacitación puntual o inexistente hace que el conocimiento se pierda y las malas prácticas se perpetúen. | V43: Implementar un plan de capacitación anual, con registro de asistencia y evaluación de efectividad. | W43: Talento Humano + DPD | X43: Nivel 5 / Optimizado
B44: M2 · Madurez Institucional | C44: CC3 | D44: III. Cultura y capacitación organizacional | E44: Cultura de privacidad por diseño en el desarrollo de nuevos proyectos o sistemas | F44: Art. 47 LOPDP | G44: A.8.25 Ciclo de vida de desarrollo seguro / A.5.34 | H44: 3 | I44: 1 | J44: 5 | K44: 1 | L44: =IF(ISNUMBER(H44),MAX(0,2-(H44-1)*0.5),IF(H44="No",2,IF(H44="Parcial",1,0))) -> 1 | M44: =IF(ISNUMBER(I44),MAX(0,2-(I44-1)*0.5),IF(I44="No",2,IF(I44="Parcial",1,0))) -> 2 | N44: =IF(ISNUMBER(J44),MAX(0,2-(J44-1)*0.5),IF(J44="No",2,IF(J44="Parcial",1,0))) -> 0 | O44: =IF(ISNUMBER(K44),MAX(0,2-(K44-1)*0.5),IF(K44="No",2,IF(K44="Parcial",1,0))) -> 2 | P44: =COUNTIF(L44:O44,">=1") -> 3 | Q44: =SUM(L44:O44) -> 5 | R44: =IF(Q44>=6,"CRÍTICA",IF(Q44>=4,"ALTA",IF(Q44>=2,"MEDIA","BAJA"))) -> ALTA | S44: =IF(R44="CRÍTICA","0-3 meses",IF(R44="ALTA","3-6 meses",IF(R44="MEDIA","6-9 meses","9-12 meses"))) -> 3-6 meses | T44: A, B, D | U44: Sin privacidad desde el diseño, los nuevos sistemas o proyectos incorporan riesgos de protección de datos evitables desde su concepción. | V44: Incluir una lista de verificación de privacidad por diseño en la adquisición o desarrollo de todo nuevo sistema. | W44: TI + DPD | X44: Nivel 5 / Optimizado
... B57: M2 · Madurez Institucional | C57: A4 | D57: VI. Auditoría, monitoreo y mejora continua | E57: Aplicación de un ciclo de mejora continua (PHVA) en la gestión de datos personales | F57: Art. 47 LOPDP | G57: Cláusula 10.1 Mejora continua | H57: 3 | I57: 1 | J57: 1 | K57: 1 | L57: =IF(ISNUMBER(H57),MAX(0,2-(H57-1)*0.5),IF(H57="No",2,IF(H57="Parcial",1,0))) -> 1 | M57: =IF(ISNUMBER(I57),MAX(0,2-(I57-1)*0.5),IF(I57="No",2,IF(I57="Parcial",1,0))) -> 2 | N57: =IF(ISNUMBER(J57),MAX(0,2-(J57-1)*0.5),IF(J57="No",2,IF(J57="Parcial",1,0))) -> 2 | O57: =IF(ISNUMBER(K57),MAX(0,2-(K57-1)*0.5),IF(K57="No",2,IF(K57="Parcial",1,0))) -> 2 | P57: =COUNTIF(L57:O57,">=1") -> 4 | Q57: =SUM(L57:O57) -> 7 | R57: =IF(Q57>=6,"CRÍTICA",IF(Q57>=4,"ALTA",IF(Q57>=2,"MEDIA","BAJA"))) -> CRÍTICA | S57: =IF(R57="CRÍTICA","0-3 meses",IF(R57="ALTA","3-6 meses",IF(R57="MEDIA","6-9 meses","9-12 meses"))) -> 0-3 meses | T57: A, B, C, D | U57: Sin ciclo PHVA, el sistema de gestión de protección de datos se estanca y no se adapta a nuevos riesgos o requisitos. | V57: Adoptar formalmente el ciclo Planificar-Hacer-Verificar-Actuar como método de gestión del sistema de protección de datos. | W57: DPD + Dirección | X57: Nivel 5 / Optimizado
B58: M3 · Gobernanza Tecnológica | C58: TG1 | D58: I. Estrategia y gobernanza TI | E58: Plan estratégico de tecnología de la información (PETI) vigente y alineado al plan institucional | F58: EGSI / buenas prácticas de gobierno TI | G58: Cláusula 5.2 Política / A.5.1 Políticas de seguridad de la información | H58: Sí | I58: Parcial | J58: No | K58: No | L58: =IF(ISNUMBER(H58),MAX(0,2-(H58-1)*0.5),IF(H58="No",2,IF(H58="Parcial",1,0))) -> 0 | M58: =IF(ISNUMBER(I58),MAX(0,2-(I58-1)*0.5),IF(I58="No",2,IF(I58="Parcial",1,0))) -> 1 | N58: =IF(ISNUMBER(J58),MAX(0,2-(J58-1)*0.5),IF(J58="No",2,IF(J58="Parcial",1,0))) -> 2 | O58: =IF(ISNUMBER(K58),MAX(0,2-(K58-1)*0.5),IF(K58="No",2,IF(K58="Parcial",1,0))) -> 2 | P58: =COUNTIF(L58:O58,">=1") -> 3 | Q58: =SUM(L58:O58) -> 5 | R58: =IF(Q58>=6,"CRÍTICA",IF(Q58>=4,"ALTA",IF(Q58>=2,"MEDIA","BAJA"))) -> ALTA | S58: =IF(R58="CRÍTICA","0-3 meses",IF(R58="ALTA","3-6 meses",IF(R58="MEDIA","6-9 meses","9-12 meses"))) -> 3-6 meses | T58: B, C, D | U58: Sin PETI, las inversiones y decisiones tecnológicas se toman de forma reactiva y desalineada de los objetivos institucionales. | V58: Elaborar un PETI a 2-3 años alineado al plan educativo institucional, incluyendo protección de datos como eje. | W58: Dirección + TI | X58: Sí / Cumple
B59: M3 · Gobernanza Tecnológica | C59: TG2 | D59: I. Estrategia y gobernanza TI | E59: Unidad o responsable formal de TI con funciones y presupuesto definidos | F59: EGSI | G59: A.5.2 Roles y responsabilidades de seguridad de la información | H59: Sí | I59: Sí | J59: Parcial | K59: No | L59: =IF(ISNUMBER(H59),MAX(0,2-(H59-1)*0.5),IF(H59="No",2,IF(H59="Parcial",1,0))) -> 0 | M59: =IF(ISNUMBER(I59),MAX(0,2-(I59-1)*0.5),IF(I59="No",2,IF(I59="Parcial",1,0))) -> 0 | N59: =IF(ISNUMBER(J59),MAX(0,2-(J59-1)*0.5),IF(J59="No",2,IF(J59="Parcial",1,0))) -> 1 | O59: =IF(ISNUMBER(K59),MAX(0,2-(K59-1)*0.5),IF(K59="No",2,IF(K59="Parcial",1,0))) -> 2 | P59: =COUNTIF(L59:O59,">=1") -> 2 | Q59: =SUM(L59:O59) -> 3 | R59: =IF(Q59>=6,"CRÍTICA",IF(Q59>=4,"ALTA",IF(Q59>=2,"MEDIA","BAJA"))) -> MEDIA | S59: =IF(R59="CRÍTICA","0-3 meses",IF(R59="ALTA","3-6 meses",IF(R59="MEDIA","6-9 meses","9-12 meses"))) -> 6-9 meses | T59: C, D | U59: Sin responsable formal de TI, la gestión tecnológica queda fragmentada y sin rendición de cuentas. | V59: Formalizar la unidad o responsable de TI, con funciones, dependencia jerárquica y presupuesto asignado. | W59: Dirección | X59: Sí / Cumple
B60: M3 · Gobernanza Tecnológica | C60: TG3 | D60: I. Estrategia y gobernanza TI | E60: Comité o instancia de toma de decisiones tecnológicas | F60: EGSI | G60: Cláusula 5.1 Liderazgo y compromiso | H60: Sí | I60: Sí | J60: No | K60: No | L60: =IF(ISNUMBER(H60),MAX(0,2-(H60-1)*0.5),IF(H60="No",2,IF(H60="Parcial",1,0))) -> 0 | M60: =IF(ISNUMBER(I60),MAX(0,2-(I60-1)*0.5),IF(I60="No",2,IF(I60="Parcial",1,0))) -> 0 | N60: =IF(ISNUMBER(J60),MAX(0,2-(J60-1)*0.5),IF(J60="No",2,IF(J60="Parcial",1,0))) -> 2 | O60: =IF(ISNUMBER(K60),MAX(0,2-(K60-1)*0.5),IF(K60="No",2,IF(K60="Parcial",1,0))) -> 2 | P60: =COUNTIF(L60:O60,">=1") -> 2 | Q60: =SUM(L60:O60) -> 4 | R60: =IF(Q60>=6,"CRÍTICA",IF(Q60>=4,"ALTA",IF(Q60>=2,"MEDIA","BAJA"))) -> ALTA | S60: =IF(R60="CRÍTICA","0-3 meses",IF(R60="ALTA","3-6 meses",IF(R60="MEDIA","6-9 meses","9-12 meses"))) -> 3-6 meses | T60: C, D | U60: Decisiones tecnológicas sin instancia formal de decisión generan inversiones inconsistentes y sin trazabilidad. | V60: Crear un comité de TI/seguridad de la información con reuniones periódicas documentadas. | W60: Dirección + TI | X60: Sí / Cumple
B61: M3 · Gobernanza Tecnológica | C61: TG4 | D61: I. Estrategia y gobernanza TI | E61: Aplicación de un marco de referencia de gobernanza TI (COBIT, ITIL, ISO 38500, ISO/IEC 27001 u otro) | F61: EGSI / mejores prácticas | G61: Cláusula 4.1-4.4 Contexto de la organización y alcance del SGSI | H61: Sí | I61: Sí | J61: Sí | K61: No | L61: =IF(ISNUMBER(H61),MAX(0,2-(H61-1)*0.5),IF(H61="No",2,IF(H61="Parcial",1,0))) -> 0 | M61: =IF(ISNUMBER(I61),MAX(0,2-(I61-1)*0.5),IF(I61="No",2,IF(I61="Parcial",1,0))) -> 0 | N61: =IF(ISNUMBER(J61),MAX(0,2-(J61-1)*0.5),IF(J61="No",2,IF(J61="Parcial",1,0))) -> 0 | O61: =IF(ISNUMBER(K61),MAX(0,2-(K61-1)*0.5),IF(K61="No",2,IF(K61="Parcial",1,0))) -> 2 | P61: =COUNTIF(L61:O61,">=1") -> 1 | Q61: =SUM(L61:O61) -> 2 | R61: =IF(Q61>=6,"CRÍTICA",IF(Q61>=4,"ALTA",IF(Q61>=2,"MEDIA","BAJA"))) -> MEDIA | S61: =IF(R61="CRÍTICA","0-3 meses",IF(R61="ALTA","3-6 meses",IF(R61="MEDIA","6-9 meses","9-12 meses"))) -> 6-9 meses | T61: D | U61: Sin marco de referencia, la gestión de TI carece de un lenguaje y estructura de controles comunes y comparables. | V61: Adoptar ISO/IEC 27001:2022 como marco de referencia principal y mapear controles existentes contra su Anexo A. | W61: TI + DPD | X61: Sí / Cumple
B62: M3 · Gobernanza Tecnológica | C62: TA1 | D62: II. Inventario y gestión de activos tecnológicos | E62: Inventario actualizado de hardware (equipos, servidores, dispositivos de red) | F62: EGSI | G62: A.5.9 Inventario de información y otros activos asociados | H62: Sí | I62: Parcial | J62: No | K62: Parcial | L62: =IF(ISNUMBER(H62),MAX(0,2-(H62-1)*0.5),IF(H62="No",2,IF(H62="Parcial",1,0))) -> 0 | M62: =IF(ISNUMBER(I62),MAX(0,2-(I62-1)*0.5),IF(I62="No",2,IF(I62="Parcial",1,0))) -> 1 | N62: =IF(ISNUMBER(J62),MAX(0,2-(J62-1)*0.5),IF(J62="No",2,IF(J62="Parcial",1,0))) -> 2 | O62: =IF(ISNUMBER(K62),MAX(0,2-(K62-1)*0.5),IF(K62="No",2,IF(K62="Parcial",1,0))) -> 1 | P62: =COUNTIF(L62:O62,">=1") -> 3 | Q62: =SUM(L62:O62) -> 4 | R62: =IF(Q62>=6,"CRÍTICA",IF(Q62>=4,"ALTA",IF(Q62>=2,"MEDIA","BAJA"))) -> ALTA | S62: =IF(R62="CRÍTICA","0-3 meses",IF(R62="ALTA","3-6 meses",IF(R62="MEDIA","6-9 meses","9-12 meses"))) -> 3-6 meses | T62: B, C, D | U62: Sin inventario de hardware no se puede garantizar que todos los equipos que procesan datos personales estén protegidos y controlados. | V62: Levantar y mantener un inventario de hardware con responsable, ubicación y criticidad. | W62: TI | X62: Sí / Cumple
B63: M3 · Gobernanza Tecnológica | C63: TA2 | D63: II. Inventario y gestión de activos tecnológicos | E63: Inventario actualizado de software y licencias | F63: EGSI | G63: A.5.9 Inventario de información y otros activos asociados / A.8.19 Instalación de software | H63: No | I63: Parcial | J63: No | K63: No | L63: =IF(ISNUMBER(H63),MAX(0,2-(H63-1)*0.5),IF(H63="No",2,IF(H63="Parcial",1,0))) -> 2 | M63: =IF(ISNUMBER(I63),MAX(0,2-(I63-1)*0.5),IF(I63="No",2,IF(I63="Parcial",1,0))) -> 1 | N63: =IF(ISNUMBER(J63),MAX(0,2-(J63-1)*0.5),IF(J63="No",2,IF(J63="Parcial",1,0))) -> 2 | O63: =IF(ISNUMBER(K63),MAX(0,2-(K63-1)*0.5),IF(K63="No",2,IF(K63="Parcial",1,0))) -> 2 | P63: =COUNTIF(L63:O63,">=1") -> 4 | Q63: =SUM(L63:O63) -> 7 | R63: =IF(Q63>=6,"CRÍTICA",IF(Q63>=4,"ALTA",IF(Q63>=2,"MEDIA","BAJA"))) -> CRÍTICA | S63: =IF(R63="CRÍTICA","0-3 meses",IF(R63="ALTA","3-6 meses",IF(R63="MEDIA","6-9 meses","9-12 meses"))) -> 0-3 meses | T63: A, B, C, D | U63: Software no inventariado puede estar sin licencia, sin actualizar o ser una puerta de entrada no controlada a los sistemas. | V63: Levantar y mantener un inventario de software y licencias, con control de instalación autorizada. | W63: TI | X63: Sí / Cumple
B64: M3 · Gobernanza Tecnológica | C64: TA3 | D64: II. Inventario y gestión de activos tecnológicos | E64: Identificación y clasificación de los sistemas de información por criticidad | F64: EGSI | G64: A.5.12 Clasificación de la información | H64: Sí | I64: Parcial | J64: No | K64: No | L64: =IF(ISNUMBER(H64),MAX(0,2-(H64-1)*0.5),IF(H64="No",2,IF(H64="Parcial",1,0))) -> 0 | M64: =IF(ISNUMBER(I64),MAX(0,2-(I64-1)*0.5),IF(I64="No",2,IF(I64="Parcial",1,0))) -> 1 | N64: =IF(ISNUMBER(J64),MAX(0,2-(J64-1)*0.5),IF(J64="No",2,IF(J64="Parcial",1,0))) -> 2 | O64: =IF(ISNUMBER(K64),MAX(0,2-(K64-1)*0.5),IF(K64="No",2,IF(K64="Parcial",1,0))) -> 2 | P64: =COUNTIF(L64:O64,">=1") -> 3 | Q64: =SUM(L64:O64) -> 5 | R64: =IF(Q64>=6,"CRÍTICA",IF(Q64>=4,"ALTA",IF(Q64>=2,"MEDIA","BAJA"))) -> ALTA | S64: =IF(R64="CRÍTICA","0-3 meses",IF(R64="ALTA","3-6 meses",IF(R64="MEDIA","6-9 meses","9-12 meses"))) -> 3-6 meses | T64: B, C, D | U64: Sin clasificación por criticidad, se asignan los mismos (o insuficientes) controles a sistemas con muy distinto nivel de riesgo. | V64: Clasificar los sistemas de información según criticidad e impacto en caso de indisponibilidad o compromiso. | W64: TI | X64: Sí / Cumple
B65: M3 · Gobernanza Tecnológica | C65: TA4 | D65: II. Inventario y gestión de activos tecnológicos | E65: Gestión del ciclo de vida de los activos tecnológicos (adquisición, operación, baja) | F65: EGSI | G65: A.5.10 Uso aceptable de los activos / A.5.11 Devolución de activos / A.7.14 Eliminación segura de equipos | H65: Sí | I65: No | J65: Parcial | K65: No | L65: =IF(ISNUMBER(H65),MAX(0,2-(H65-1)*0.5),IF(H65="No",2,IF(H65="Parcial",1,0))) -> 0 | M65: =IF(ISNUMBER(I65),MAX(0,2-(I65-1)*0.5),IF(I65="No",2,IF(I65="Parcial",1,0))) -> 2 | N65: =IF(ISNUMBER(J65),MAX(0,2-(J65-1)*0.5),IF(J65="No",2,IF(J65="Parcial",1,0))) -> 1 | O65: =IF(ISNUMBER(K65),MAX(0,2-(K65-1)*0.5),IF(K65="No",2,IF(K65="Parcial",1,0))) -> 2 | P65: =COUNTIF(L65:O65,">=1") -> 3 | Q65: =SUM(L65:O65) -> 5 | R65: =IF(Q65>=6,"CRÍTICA",IF(Q65>=4,"ALTA",IF(Q65>=2,"MEDIA","BAJA"))) -> ALTA | S65: =IF(R65="CRÍTICA","0-3 meses",IF(R65="ALTA","3-6 meses",IF(R65="MEDIA","6-9 meses","9-12 meses"))) -> 3-6 meses | T65: B, C, D | U65: Equipos dados de baja sin procedimiento seguro pueden filtrar datos personales almacenados en ellos. | V65: Definir el procedimiento de ciclo de vida de activos, incluyendo borrado seguro previo a la baja o reasignación. | W65: TI | X65: Sí / Cumple
B66: M3 · Gobernanza Tecnológica | C66: SI1 | D66: III. Sistemas de información y bases de datos | E66: Sistemas de información documentados (arquitectura, flujos de datos, usuarios) | F66: EGSI | G66: A.5.9 / A.8.9 Gestión de la configuración | H66: Sí | I66: Parcial | J66: No | K66: No | L66: =IF(ISNUMBER(H66),MAX(0,2-(H66-1)*0.5),IF(H66="No",2,IF(H66="Parcial",1,0))) -> 0 | M66: =IF(ISNUMBER(I66),MAX(0,2-(I66-1)*0.5),IF(I66="No",2,IF(I66="Parcial",1,0))) -> 1 | N66: =IF(ISNUMBER(J66),MAX(0,2-(J66-1)*0.5),IF(J66="No",2,IF(J66="Parcial",1,0))) -> 2 | O66: =IF(ISNUMBER(K66),MAX(0,2-(K66-1)*0.5),IF(K66="No",2,IF(K66="Parcial",1,0))) -> 2 | P66: =COUNTIF(L66:O66,">=1") -> 3 | Q66: =SUM(L66:O66) -> 5 | R66: =IF(Q66>=6,"CRÍTICA",IF(Q66>=4,"ALTA",IF(Q66>=2,"MEDIA","BAJA"))) -> ALTA | S66: =IF(R66="CRÍTICA","0-3 meses",IF(R66="ALTA","3-6 meses",IF(R66="MEDIA","6-9 meses","9-12 meses"))) -> 3-6 meses | T66: B, C, D | U66: Sistemas no documentados dependen del conocimiento tácito de una persona y son difíciles de asegurar o auditar. | V66: Documentar la arquitectura, flujos de datos y usuarios de los sistemas de información institucionales. | W66: TI | X66: Sí / Cumple
B67: M3 · Gobernanza Tecnológica | C67: SI2 | D67: III. Sistemas de información y bases de datos | E67: Integración entre los sistemas de información documentada | F67: EGSI | G67: A.8.9 Gestión de la configuración / A.5.9 | H67: No | I67: Parcial | J67: Parcial | K67: No | L67: =IF(ISNUMBER(H67),MAX(0,2-(H67-1)*0.5),IF(H67="No",2,IF(H67="Parcial",1,0))) -> 2 | M67: =IF(ISNUMBER(I67),MAX(0,2-(I67-1)*0.5),IF(I67="No",2,IF(I67="Parcial",1,0))) -> 1 | N67: =IF(ISNUMBER(J67),MAX(0,2-(J67-1)*0.5),IF(J67="No",2,IF(J67="Parcial",1,0))) -> 1 | O67: =IF(ISNUMBER(K67),MAX(0,2-(K67-1)*0.5),IF(K67="No",2,IF(K67="Parcial",1,0))) -> 2 | P67: =COUNTIF(L67:O67,">=1") -> 4 | Q67: =SUM(L67:O67) -> 6 | R67: =IF(Q67>=6,"CRÍTICA",IF(Q67>=4,"ALTA",IF(Q67>=2,"MEDIA","BAJA"))) -> CRÍTICA | S67: =IF(R67="CRÍTICA","0-3 meses",IF(R67="ALTA","3-6 meses",IF(R67="MEDIA","6-9 meses","9-12 meses"))) -> 0-3 meses | T67: A, B, C, D | U67: Integraciones no documentadas generan puntos ciegos de seguridad y dificultan detectar fugas de datos entre sistemas. | V67: Documentar las integraciones existentes (APIs, exportaciones, sincronizaciones) entre sistemas. | W67: TI | X67: Sí / Cumple
B68: M3 · Gobernanza Tecnológica | C68: SI3 | D68: III. Sistemas de información y bases de datos | E68: Controles de acceso basados en roles (RBAC) o perfiles de usuario | F68: EGSI | G68: A.5.15 Control de acceso / A.8.2 Derechos de acceso privilegiado / A.8.3 Restricción de acceso a la información | H68: Parcial | I68: No | J68: No | K68: No | L68: =IF(ISNUMBER(H68),MAX(0,2-(H68-1)*0.5),IF(H68="No",2,IF(H68="Parcial",1,0))) -> 1 | M68: =IF(ISNUMBER(I68),MAX(0,2-(I68-1)*0.5),IF(I68="No",2,IF(I68="Parcial",1,0))) -> 2 | N68: =IF(ISNUMBER(J68),MAX(0,2-(J68-1)*0.5),IF(J68="No",2,IF(J68="Parcial",1,0))) -> 2 | O68: =IF(ISNUMBER(K68),MAX(0,2-(K68-1)*0.5),IF(K68="No",2,IF(K68="Parcial",1,0))) -> 2 | P68: =COUNTIF(L68:O68,">=1") -> 4 | Q68: =SUM(L68:O68) -> 7 | R68: =IF(Q68>=6,"CRÍTICA",IF(Q68>=4,"ALTA",IF(Q68>=2,"MEDIA","BAJA"))) -> CRÍTICA | S68: =IF(R68="CRÍTICA","0-3 meses",IF(R68="ALTA","3-6 meses",IF(R68="MEDIA","6-9 meses","9-12 meses"))) -> 0-3 meses | T68: A, B, C, D | U68: Sin control de acceso basado en roles, cualquier usuario puede ver o modificar datos personales fuera de su función, violando el principio de mínimo privilegio. | V68: Implementar perfiles de acceso por rol en todos los sistemas que traten datos personales, con revisión periódica de permisos. | W68: TI | X68: Sí / Cumple
B69: M3 · Gobernanza Tecnológica | C69: SI4 | D69: III. Sistemas de información y bases de datos | E69: Registro de logs de auditoría en los sistemas de información (accesos, cambios, consultas) | F69: EGSI | G69: A.8.15 Registro (logging) / A.8.16 Actividades de monitoreo | H69: Sí | I69: Parcial | J69: Parcial | K69: No | L69: =IF(ISNUMBER(H69),MAX(0,2-(H69-1)*0.5),IF(H69="No",2,IF(H69="Parcial",1,0))) -> 0 | M69: =IF(ISNUMBER(I69),MAX(0,2-(I69-1)*0.5),IF(I69="No",2,IF(I69="Parcial",1,0))) -> 1 | N69: =IF(ISNUMBER(J69),MAX(0,2-(J69-1)*0.5),IF(J69="No",2,IF(J69="Parcial",1,0))) -> 1 | O69: =IF(ISNUMBER(K69),MAX(0,2-(K69-1)*0.5),IF(K69="No",2,IF(K69="Parcial",1,0))) -> 2 | P69: =COUNTIF(L69:O69,">=1") -> 3 | Q69: =SUM(L69:O69) -> 4 | R69: =IF(Q69>=6,"CRÍTICA",IF(Q69>=4,"ALTA",IF(Q69>=2,"MEDIA","BAJA"))) -> ALTA | S69: =IF(R69="CRÍTICA","0-3 meses",IF(R69="ALTA","3-6 meses",IF(R69="MEDIA","6-9 meses","9-12 meses"))) -> 3-6 meses | T69: B, C, D | U69: Sin logs, ante un incidente es imposible determinar qué datos fueron accedidos, por quién y cuándo. | V69: Habilitar el registro de logs de acceso y cambios en los sistemas críticos, con retención y revisión periódica. | W69: TI | X69: Sí / Cumple
...

Sheet Resumen Ejecutivo
B2: RESUMEN EJECUTIVO DE BRECHAS
B4: 1. BRECHAS POR MÓDULO Y PRIORIDAD
B5: Módulo | C5: CRÍTICA | D5: ALTA | E5: MEDIA | F5: BAJA | G5: Total criterios
B6: M1 · Cumplimiento LOPDP/RGLOPDP | C6: =COUNTIFS('Matriz Consolidada'!$B$4:$B$85,$B6,'Matriz Consolidada'!$R$4:$R$85,C$5) -> 14 | D6: =COUNTIFS('Matriz Consolidada'!$B$4:$B$85,$B6,'Matriz Consolidada'!$R$4:$R$85,D$5) -> 11 | E6: =COUNTIFS('Matriz Consolidada'!$B$4:$B$85,$B6,'Matriz Consolidada'!$R$4:$R$85,E$5) -> 3 | F6: =COUNTIFS('Matriz Consolidada'!$B$4:$B$85,$B6,'Matriz Consolidada'!$R$4:$R$85,F$5) -> 1 | G6: =SUM(C6:F6) -> 29
B7: M2 · Madurez Institucional | C7: =COUNTIFS('Matriz Consolidada'!$B$4:$B$85,$B7,'Matriz Consolidada'!$R$4:$R$85,C$5) -> 17 | D7: =COUNTIFS('Matriz Consolidada'!$B$4:$B$85,$B7,'Matriz Consolidada'!$R$4:$R$85,D$5) -> 8 | E7: =COUNTIFS('Matriz Consolidada'!$B$4:$B$85,$B7,'Matriz Consolidada'!$R$4:$R$85,E$5) -> 0 | F7: =COUNTIFS('Matriz Consolidada'!$B$4:$B$85,$B7,'Matriz Consolidada'!$R$4:$R$85,F$5) -> 0 | G7: =SUM(C7:F7) -> 25
B8: M3 · Gobernanza Tecnológica | C8: =COUNTIFS('Matriz Consolidada'!$B$4:$B$85,$B8,'Matriz Consolidada'!$R$4:$R$85,C$5) -> 10 | D8: =COUNTIFS('Matriz Consolidada'!$B$4:$B$85,$B8,'Matriz Consolidada'!$R$4:$R$85,D$5) -> 15 | E8: =COUNTIFS('Matriz Consolidada'!$B$4:$B$85,$B8,'Matriz Consolidada'!$R$4:$R$85,E$5) -> 3 | F8: =COUNTIFS('Matriz Consolidada'!$B$4:$B$85,$B8,'Matriz Consolidada'!$R$4:$R$85,F$5) -> 0 | G8: =SUM(C8:F8) -> 28
B9: TOTAL | C9: =SUM(C6:C8) -> 41 | D9: =SUM(D6:D8) -> 34 | E9: =SUM(E6:E8) -> 6 | F9: =SUM(F6:F8) -> 1 | G9: =SUM(G6:G8) -> 82
B12: 2. BRECHAS ABIERTAS POR INSTITUCIÓN Y MÓDULO (criterios con Pts ≥ 1)
B13: Módulo | C13: Institución A | D13: Institución B | E13: Institución C | F13: Institución D | G13: Total criterios del módulo
B14: M1 · Cumplimiento LOPDP/RGLOPDP | C14: =COUNTIFS('Matriz Consolidada'!$B$4:$B$85,$B14,'Matriz Consolidada'!$L$4:$L$85,">=1") -> 20 | D14: =COUNTIFS('Matriz Consolidada'!$B$4:$B$85,$B14,'Matriz Consolidada'!$M$4:$M$85,">=1") -> 21 | E14: =COUNTIFS('Matriz Consolidada'!$B$4:$B$85,$B14,'Matriz Consolidada'!$N$4:$N$85,">=1") -> 27 | F14: =COUNTIFS('Matriz Consolidada'!$B$4:$B$85,$B14,'Matriz Consolidada'!$O$4:$O$85,">=1") -> 27 | G14: =COUNTIF('Matriz Consolidada'!$B$4:$B$85,$B14) -> 29
B15: M2 · Madurez Institucional | C15: =COUNTIFS('Matriz Consolidada'!$B$4:$B$85,$B15,'Matriz Consolidada'!$L$4:$L$85,">=1") -> 19 | D15: =COUNTIFS('Matriz Consolidada'!$B$4:$B$85,$B15,'Matriz Consolidada'!$M$4:$M$85,">=1") -> 25 | E15: =COUNTIFS('Matriz Consolidada'!$B$4:$B$85,$B15,'Matriz Consolidada'!$N$4:$N$85,">=1") -> 23 | F15: =COUNTIFS('Matriz Consolidada'!$B$4:$B$85,$B15,'Matriz Consolidada'!$O$4:$O$85,">=1") -> 25 | G15: =COUNTIF('Matriz Consolidada'!$B$4:$B$85,$B15) -> 25
B16: M3 · Gobernanza Tecnológica | C16: =COUNTIFS('Matriz Consolidada'!$B$4:$B$85,$B16,'Matriz Consolidada'!$L$4:$L$85,">=1") -> 10 | D16: =COUNTIFS('Matriz Consolidada'!$B$4:$B$85,$B16,'Matriz Consolidada'!$M$4:$M$85,">=1") -> 22 | E16: =COUNTIFS('Matriz Consolidada'!$B$4:$B$85,$B16,'Matriz Consolidada'!$N$4:$N$85,">=1") -> 27 | F16: =COUNTIFS('Matriz Consolidada'!$B$4:$B$85,$B16,'Matriz Consolidada'!$O$4:$O$85,">=1") -> 28 | G16: =COUNTIF('Matriz Consolidada'!$B$4:$B$85,$B16) -> 28
B19: 3. ÍNDICE DE CUMPLIMIENTO ACTUAL VS. META (100% LOPDP)
B20: Institución | C20: Módulo 1 (% actual) | D20: Módulo 2 (% madurez) | E20: Módulo 3 (% actual) | F20: Índice global (% actual) | G20: Meta | H20: Brecha a cerrar (pts %)
B21: Institución A | C21: 0.44827586 | D21: 0.488 | E21: 0.71428571 | F21: 0.55018719 | G21: 1 | H21: =G21-F21 -> 0.44981281
B22: Institución B | C22: 0.31034483 | D22: 0.328 | E22: 0.42857143 | F22: 0.35563875 | G22: 1 | H22: =G22-F22 -> 0.64436125
B23: Institución C | C23: 0.31034483 | D23: 0.376 | E23: 0.26785714 | F23: 0.31806732 | G23: 1 | H23: =G23-F23 -> 0.68193268
B24: Institución D | C24: 0.12068966 | D24: 0.216 | E24: 0.017857143 | F24: 0.11818227 | G24: 1 | H24: =G24-F24 -> 0.88181773

Sheet Hoja de Ruta_100pct
B2: HOJA DE RUTA CONSOLIDADA HACIA EL 100% DE CUMPLIMIENTO LOPDP
B3: Cronograma de cierre de brechas por tramo de prioridad, para las 4 instituciones evaluadas
B5: TOTAL DE CRITERIOS EVALUADOS POR EL MODELO | C5: 82
B7: Tramo (plazo sugerido) | C7: Criterios a cerrar Institución A | D7: Criterios a cerrar Institución B | E7: Criterios a cerrar Institución C | F7: Criterios a cerrar Institución D | G7: % cumplimiento proyectado (promedio 4 instituciones)
B8: 0-3 meses (prioridad CRÍTICA) | C8: =COUNTIFS('Matriz Consolidada'!$S$4:$S$85,"0-3 meses",'Matriz Consolidada'!$L$4:$L$85,">=1") -> 38 | D8: =COUNTIFS('Matriz Consolidada'!$S$4:$S$85,"0-3 meses",'Matriz Consolidada'!$M$4:$M$85,">=1") -> 41 | E8: =COUNTIFS('Matriz Consolidada'!$S$4:$S$85,"0-3 meses",'Matriz Consolidada'!$N$4:$N$85,">=1") -> 41 | F8: =COUNTIFS('Matriz Consolidada'!$S$4:$S$85,"0-3 meses",'Matriz Consolidada'!$O$4:$O$85,">=1") -> 40 | G8: =AVERAGE(((82-(SUM('Resumen Ejecutivo'!C14:C16)-SUM(C$8:C8)))/82),((82-(SUM('Resumen Ejecutivo'!D14:D16)-SUM(D$8:D8)))/82),((82-(SUM('Resumen Ejecutivo'!E14:E16)-SUM(E$8:E8)))/82),((82-(SUM('Resumen Ejecutivo'!F14:F16)-SUM(F$8:F8)))/82)) -> 0.65243902
B9: 3-6 meses (prioridad ALTA) | C9: =COUNTIFS('Matriz Consolidada'!$S$4:$S$85,"3-6 meses",'Matriz Consolidada'!$L$4:$L$85,">=1") -> 10 | D9: =COUNTIFS('Matriz Consolidada'!$S$4:$S$85,"3-6 meses",'Matriz Consolidada'!$M$4:$M$85,">=1") -> 27 | E9: =COUNTIFS('Matriz Consolidada'!$S$4:$S$85,"3-6 meses",'Matriz Consolidada'!$N$4:$N$85,">=1") -> 32 | F9: =COUNTIFS('Matriz Consolidada'!$S$4:$S$85,"3-6 meses",'Matriz Consolidada'!$O$4:$O$85,">=1") -> 33 | G9: =AVERAGE(((82-(SUM('Resumen Ejecutivo'!C14:C16)-SUM(C$8:C9)))/82),((82-(SUM('Resumen Ejecutivo'!D14:D16)-SUM(D$8:D9)))/82),((82-(SUM('Resumen Ejecutivo'!E14:E16)-SUM(E$8:E9)))/82),((82-(SUM('Resumen Ejecutivo'!F14:F16)-SUM(F$8:F9)))/82)) -> 0.96341463
B10: 6-9 meses (prioridad MEDIA) | C10: =COUNTIFS('Matriz Consolidada'!$S$4:$S$85,"6-9 meses",'Matriz Consolidada'!$L$4:$L$85,">=1") -> 1 | D10: =COUNTIFS('Matriz Consolidada'!$S$4:$S$85,"6-9 meses",'Matriz Consolidada'!$M$4:$M$85,">=1") -> 0 | E10: =COUNTIFS('Matriz Consolidada'!$S$4:$S$85,"6-9 meses",'Matriz Consolidada'!$N$4:$N$85,">=1") -> 4 | F10: =COUNTIFS('Matriz Consolidada'!$S$4:$S$85,"6-9 meses",'Matriz Consolidada'!$O$4:$O$85,">=1") -> 6 | G10: =AVERAGE(((82-(SUM('Resumen Ejecutivo'!C14:C16)-SUM(C$8:C10)))/82),((82-(SUM('Resumen Ejecutivo'!D14:D16)-SUM(D$8:D10)))/82),((82-(SUM('Resumen Ejecutivo'!E14:E16)-SUM(E$8:E10)))/82),((82-(SUM('Resumen Ejecutivo'!F14:F16)-SUM(F$8:F10)))/82)) -> 0.99695122
B11: 9-12 meses (prioridad BAJA) | C11: =COUNTIFS('Matriz Consolidada'!$S$4:$S$85,"9-12 meses",'Matriz Consolidada'!$L$4:$L$85,">=1") -> 0 | D11: =COUNTIFS('Matriz Consolidada'!$S$4:$S$85,"9-12 meses",'Matriz Consolidada'!$M$4:$M$85,">=1") -> 0 | E11: =COUNTIFS('Matriz Consolidada'!$S$4:$S$85,"9-12 meses",'Matriz Consolidada'!$N$4:$N$85,">=1") -> 0 | F11: =COUNTIFS('Matriz Consolidada'!$S$4:$S$85,"9-12 meses",'Matriz Consolidada'!$O$4:$O$85,">=1") -> 1 | G11: =AVERAGE(((82-(SUM('Resumen Ejecutivo'!C14:C16)-SUM(C$8:C11)))/82),((82-(SUM('Resumen Ejecutivo'!D14:D16)-SUM(D$8:D11)))/82),((82-(SUM('Resumen Ejecutivo'!E14:E16)-SUM(E$8:E11)))/82),((82-(SUM('Resumen Ejecutivo'!F14:F16)-SUM(F$8:F11)))/82)) -> 1

Sheet Mapa ISO27001
B2: TRAZABILIDAD LOPDP - ISO/IEC 27001:2022
B4: Control ISO/IEC 27001:2022 (Anexo A / cláusula) | C4: N° criterios asociados | D4: Inst. A con brecha | E4: Inst. B con brecha | F4: Inst. C con brecha | G4: Inst. D con brecha
B5: A.5.9 Inventario de información y otros activos asociados | C5: =COUNTIF('Matriz Consolidada'!$G$4:$G$85,"A.5.9 Inventario de información y otros activos asociados") -> 3 | D5: =COUNTIFS('Matriz Consolidada'!$G$4:$G$85,"A.5.9 Inventario de información y otros activos asociados",'Matriz Consolidada'!$L$4:$L$85,">=1") -> 2 | E5: =COUNTIFS('Matriz Consolidada'!$G$4:$G$85,"A.5.9 Inventario de información y otros activos asociados",'Matriz Consolidada'!$M$4:$M$85,">=1") -> 2 | F5: =COUNTIFS('Matriz Consolidada'!$G$4:$G$85,"A.5.9 Inventario de información y otros activos asociados",'Matriz Consolidada'!$N$4:$N$85,">=1") -> 2 | G5: =COUNTIFS('Matriz Consolidada'!$G$4:$G$85,"A.5.9 Inventario de información y otros activos asociados",'Matriz Consolidada'!$O$4:$O$85,">=1") -> 3
B6: A.5.12 Clasificación de la información | C6: =COUNTIF('Matriz Consolidada'!$G$4:$G$85,"A.5.12 Clasificación de la información") -> 2 | D6: =COUNTIFS('Matriz Consolidada'!$G$4:$G$85,"A.5.12 Clasificación de la información",'Matriz Consolidada'!$L$4:$L$85,">=1") -> 0 | E6: =COUNTIFS('Matriz Consolidada'!$G$4:$G$85,"A.5.12 Clasificación de la información",'Matriz Consolidada'!$M$4:$M$85,">=1") -> 1 | F6: =COUNTIFS('Matriz Consolidada'!$G$4:$G$85,"A.5.12 Clasificación de la información",'Matriz Consolidada'!$N$4:$N$85,">=1") -> 1 | G6: =COUNTIFS('Matriz Consolidada'!$G$4:$G$85,"A.5.12 Clasificación de la información",'Matriz Consolidada'!$O$4:$O$85,">=1") -> 2
B7: A.5.33 Protección de los registros | C7: =COUNTIF('Matriz Consolidada'!$G$4:$G$85,"A.5.33 Protección de los registros") -> 1 | D7: =COUNTIFS('Matriz Consolidada'!$G$4:$G$85,"A.5.33 Protección de los registros",'Matriz Consolidada'!$L$4:$L$85,">=1") -> 0 | E7: =COUNTIFS('Matriz Consolidada'!$G$4:$G$85,"A.5.33 Protección de los registros",'Matriz Consolidada'!$M$4:$M$85,">=1") -> 0 | F7: =COUNTIFS('Matriz Consolidada'!$G$4:$G$85,"A.5.33 Protección de los registros",'Matriz Consolidada'!$N$4:$N$85,">=1") -> 1 | G7: =COUNTIFS('Matriz Consolidada'!$G$4:$G$85,"A.5.33 Protección de los registros",'Matriz Consolidada'!$O$4:$O$85,">=1") -> 1
